Failure # 1 (occurred at 2022-04-29_17-23-09)
Traceback (most recent call last):
  File "/Users/mylesfoley/opt/anaconda3/lib/python3.8/site-packages/ray/tune/trial_runner.py", line 924, in _process_trial
    results = self.trial_executor.fetch_result(trial)
  File "/Users/mylesfoley/opt/anaconda3/lib/python3.8/site-packages/ray/tune/ray_trial_executor.py", line 787, in fetch_result
    result = ray.get(trial_future[0], timeout=DEFAULT_GET_TIMEOUT)
  File "/Users/mylesfoley/opt/anaconda3/lib/python3.8/site-packages/ray/_private/client_mode_hook.py", line 105, in wrapper
    return func(*args, **kwargs)
  File "/Users/mylesfoley/opt/anaconda3/lib/python3.8/site-packages/ray/worker.py", line 1713, in get
    raise value.as_instanceof_cause()
ray.exceptions.RayTaskError(AssertionError): [36mray::PPO.train()[39m (pid=10772, ip=127.0.0.1, repr=PPO)
  File "/Users/mylesfoley/opt/anaconda3/lib/python3.8/site-packages/ray/tune/trainable.py", line 314, in train
    result = self.step()
  File "/Users/mylesfoley/opt/anaconda3/lib/python3.8/site-packages/ray/rllib/agents/trainer.py", line 885, in step
    raise e
  File "/Users/mylesfoley/opt/anaconda3/lib/python3.8/site-packages/ray/rllib/agents/trainer.py", line 867, in step
    result = self.step_attempt()
  File "/Users/mylesfoley/opt/anaconda3/lib/python3.8/site-packages/ray/rllib/agents/trainer.py", line 920, in step_attempt
    step_results = next(self.train_exec_impl)
  File "/Users/mylesfoley/opt/anaconda3/lib/python3.8/site-packages/ray/util/iter.py", line 756, in __next__
    return next(self.built_iterator)
  File "/Users/mylesfoley/opt/anaconda3/lib/python3.8/site-packages/ray/util/iter.py", line 783, in apply_foreach
    for item in it:
  File "/Users/mylesfoley/opt/anaconda3/lib/python3.8/site-packages/ray/util/iter.py", line 783, in apply_foreach
    for item in it:
  File "/Users/mylesfoley/opt/anaconda3/lib/python3.8/site-packages/ray/util/iter.py", line 843, in apply_filter
    for item in it:
  File "/Users/mylesfoley/opt/anaconda3/lib/python3.8/site-packages/ray/util/iter.py", line 843, in apply_filter
    for item in it:
  File "/Users/mylesfoley/opt/anaconda3/lib/python3.8/site-packages/ray/util/iter.py", line 783, in apply_foreach
    for item in it:
  File "/Users/mylesfoley/opt/anaconda3/lib/python3.8/site-packages/ray/util/iter.py", line 783, in apply_foreach
    for item in it:
  File "/Users/mylesfoley/opt/anaconda3/lib/python3.8/site-packages/ray/util/iter.py", line 783, in apply_foreach
    for item in it:
  [Previous line repeated 1 more time]
  File "/Users/mylesfoley/opt/anaconda3/lib/python3.8/site-packages/ray/util/iter.py", line 876, in apply_flatten
    for item in it:
  File "/Users/mylesfoley/opt/anaconda3/lib/python3.8/site-packages/ray/util/iter.py", line 783, in apply_foreach
    for item in it:
  File "/Users/mylesfoley/opt/anaconda3/lib/python3.8/site-packages/ray/util/iter.py", line 783, in apply_foreach
    for item in it:
  File "/Users/mylesfoley/opt/anaconda3/lib/python3.8/site-packages/ray/util/iter.py", line 783, in apply_foreach
    for item in it:
  File "/Users/mylesfoley/opt/anaconda3/lib/python3.8/site-packages/ray/rllib/execution/rollout_ops.py", line 76, in sampler
    yield workers.local_worker().sample()
  File "/Users/mylesfoley/opt/anaconda3/lib/python3.8/site-packages/ray/rllib/evaluation/rollout_worker.py", line 757, in sample
    batches = [self.input_reader.next()]
  File "/Users/mylesfoley/opt/anaconda3/lib/python3.8/site-packages/ray/rllib/evaluation/sampler.py", line 103, in next
    batches = [self.get_data()]
  File "/Users/mylesfoley/opt/anaconda3/lib/python3.8/site-packages/ray/rllib/evaluation/sampler.py", line 265, in get_data
    item = next(self._env_runner)
  File "/Users/mylesfoley/opt/anaconda3/lib/python3.8/site-packages/ray/rllib/evaluation/sampler.py", line 633, in _env_runner
    _process_observations(
  File "/Users/mylesfoley/opt/anaconda3/lib/python3.8/site-packages/ray/rllib/evaluation/sampler.py", line 848, in _process_observations
    prep_obs = preprocessor.transform(raw_obs)
  File "/Users/mylesfoley/opt/anaconda3/lib/python3.8/site-packages/ray/rllib/models/preprocessors.py", line 238, in transform
    self.write(observation, array, 0)
  File "/Users/mylesfoley/opt/anaconda3/lib/python3.8/site-packages/ray/rllib/models/preprocessors.py", line 244, in write
    assert len(observation) == len(self.preprocessors), observation
AssertionError: [array([[0, 0, 0, 0, 0, 0, 0, 0, 0, 0, 0, 0, 0, 0, 0, 0, 0, 0, 0, 0, 0, 0,
        0, 0, 0, 0, 0, 0, 0, 0, 0, 0, 0, 0, 0, 0, 0, 0, 0, 0, 0, 0, 0, 0,
        1, 0, 0, 0, 0, 0, 0, 0]]), 5]

